<?xml version="1.0"?>
<robot name="visual">

<material name="blue">
    <color rgba="0 0 0.8 1"/>
</material>
<material name="red">
    <color rgba="0.8 0 0 1"/>
</material>
<material name="green">
    <color rgba="0 0.8 0 1"/>
</material>
<material name="black">
    <color rgba="0 0 0 1"/>
</material>
<material name="white">
    <color rgba="1 1 1 1"/>
</material>
<material name="yellow">
    <color rgba="1 1 0 1"/>
</material>
<material name="orange">
    <color rgba="1 0.5 0 1"/>
</material>

  <link name="base_link">
    <visual>
      <geometry>
        <box size="0.2 0.2 0.1"/>
      </geometry>
      <material name="orange"/>
    </visual>
  </link>

  <link name="front_frame">
    <visual>
      <geometry>
        <box size="0.2 0.25 0.05"/>
      </geometry>
      <origin rpy="0 0 0" xyz="0 0 0"/>
      <material name="orange"/>
    </visual>
  </link>

  <joint name="base_to_front_frame" type="fixed">
    <parent link="base_link"/>
    <child link="front_frame"/>
    <origin xyz="0 -0.2 -0.1"/>
  </joint>

  <link name="front_base">
    <visual>
      <geometry>
        <box size="0.4 0.05 0.05"/>
      </geometry>
      <material name="green"/>
    </visual>
  </link>

  <joint name="front_base_joint" type="fixed">
    <parent link="front_frame"/>
    <child link="front_base"/>
    <origin xyz="0.1 -0.125 -0.05"/>
  </joint>

  <link name="front_right_wheel">
    <visual>
      <origin rpy="0 4.725 0" xyz="0 0 0"/>
      <geometry>
        <cylinder length="0.1" radius="0.15"/>
      </geometry>
      <material name="black"/>
    </visual>
  </link>

  <joint name="front_right_wheel_joint" type="continuous">
    <axis rpy="0 0 0" xyz="0 1 0"/>
    <parent link="front_base"/>
    <child link="front_right_wheel"/>
    <origin rpy="0 0 0" xyz="0.25 0 -0.1"/>
  </joint>

  <link name="front_left_wheel">
    <visual>
      <origin rpy="0 4.725 0" xyz="0 0 0"/>
      <geometry>
        <cylinder length="0.1" radius="0.15"/>
      </geometry>
      <material name="black"/>
    </visual>
  </link>
  <joint name="front_left_wheel_joint" type="continuous">
    <axis rpy="0 0 0" xyz="0 1 0"/>
    <parent link="front_base"/>
    <child link="front_left_wheel"/>
    <origin rpy="0 0 0" xyz="-0.25 0 -0.1"/>
  </joint>

  <link name="back_frame">
    <visual>
      <geometry>
        <box size="0.2 0.25 0.05"/>
      </geometry>
      <origin rpy="0 0 0" xyz="0 0 0"/>
      <material name="orange"/>
    </visual>
  </link>

  <joint name="base_to_back_frame" type="fixed">
    <parent link="base_link"/>
    <child link="back_frame"/>
    <origin xyz="0 0.2 -0.1"/>
  </joint>

  <link name="back_base">
    <visual>
      <geometry>
        <box size="0.4 0.05 0.05"/>
      </geometry>
      <material name="red"/>
    </visual>
  </link>

  <joint name="back_base_joint" type="fixed">
    <parent link="back_frame"/>
    <child link="back_base"/>
    <origin xyz="0.1 0.125 -0.05"/>
  </joint>

  <link name="back_right_wheel">
    <visual>
      <origin rpy="0 4.725 0" xyz="0 0 0"/>
      <geometry>
        <cylinder length="0.1" radius="0.15"/>
      </geometry>
      <material name="black"/>
    </visual>
  </link>
  <joint name="back_right_wheel_joint" type="continuous">
    <axis rpy="0 0 0" xyz="0 1 0"/>
    <parent link="back_base"/>
    <child link="back_right_wheel"/>
    <origin rpy="0 0 0" xyz="0.25 0 -0.1"/>
  </joint>

  <link name="back_left_wheel">
    <visual>
      <origin rpy="0 4.725 0" xyz="0 0 0"/>
      <geometry>
        <cylinder length="0.1" radius="0.15"/>
      </geometry>
      <material name="black"/>
    </visual>
  </link>
  <joint name="back_left_wheel_joint" type="continuous">
    <axis rpy="0 0 0" xyz="0 1 0"/>
    <parent link="back_base"/>
    <child link="back_left_wheel"/>
    <origin rpy="0 0 0" xyz="-0.25 0 -0.1"/>
  </joint>

  <link name="gripper_arm1">
    <visual>
      <geometry>
        <origin rpy="0 4.75 0" xyz="0 0 0"/>
        <box size="0.6 0.1 0.2"/>
      </geometry>
      <material name="black"/>
    </visual>
  </link>

  <joint name="gripper_extension1" type="fixed">
    <parent link="base_link"/>
    <child link="gripper_arm1"/>
    <limit effort="1000.0" lower="-0.38" upper="0" velocity="0.5"/>
    <origin rpy="0 0 0" xyz="0 0 1"/>
  </joint>

  <link name="gripper_arm2">
    <visual>
      <geometry>
        <origin rpy="0 4.75 0" xyz="0 0 0"/>
        <box size="0.6 0.1 0.2"/>
      </geometry>
      <material name="white"/>
    </visual>
  </link>

  <joint name="gripper_extension2" type="fixed">
    <parent link="gripper_arm1"/>
    <child link="gripper_arm2"/>
    <limit effort="1000.0" lower="-0.38" upper="0" velocity="0.5"/>
    <origin rpy="0 0 0" xyz="0 0 0.6"/>
  </joint>

  <link name="wrist_base">
    <visual>
      <geometry>
        <box size="0.05 0.05 0.05"/>
      </geometry>
      <material name="blue"/>
    </visual>
  </link>

  <joint name="wrist_joint" type="fixed">
    <parent link="gripper_arm2"/>
    <child link="wrist_base"/>
    <limit effort="1000.0" lower="-0.38" upper="0" velocity="0.5"/>
    <origin rpy="0 4.75 0" xyz="0 0 -0.05"/>
  </joint>

  <link name="left_gripper">
    <visual>
      <origin rpy="0 4.75 0" xyz="0 0 0"/>
      <geometry>
        <mesh filename="package://urdf_tutorial/meshes/l_finger.dae"/>
      </geometry>
    </visual>
  </link>

  <link name="right_gripper">
    <visual>
     <origin rpy="0 4.75 0" xyz="0 0 0"/>
     <geometry>
        <mesh filename="package://urdf_tutorial/meshes/l_finger.dae"/>
      </geometry>
    </visual>
  </link>

  <joint name="left_gripper_joint" type="revolute">
    <axis xyz="0 0 1"/>
    <limit effort="1000.0" lower="0.0" upper="0.548" velocity="0.5"/>
    <origin rpy="0 0 0" xyz="0.2 0.01 0"/>
    <parent link="wrist_base"/>
    <child link="left_gripper"/>
  </joint>

  <joint name="right_gripper_joint" type="revolute">
    <axis xyz="0 0 -1"/>
    <limit effort="1000.0" lower="0.0" upper="0.548" velocity="0.5"/>
    <origin rpy="0 0 0" xyz="0.2 -0.01 0"/>
    <parent link="wrist_base"/>
    <child link="right_gripper"/>
  </joint>

  <link name="camera_front">
    <visual>
      <geometry>
        <sphere radius="0.01"/>
      </geometry>
      <material name="yellow"/>
    </visual>
  </link>
  <joint name="camera_swivel" type="continuous">
    <parent link="base_link"/>
    <child link="camera_front"/>
    <axis xyz="0 0 1"/>
    <origin xyz="0 0 0.3"/>
  </joint>

</robot>
